Workbook
Name DealNoDefault: '184119 - RUBIS - BEIRA-LSK'!$O$5
Name DealNoDefault: '184182-RUBIS-BEIRA-LSK'!$O$5
Name DealNoDefault: '184752 - RUBIS - BEIRA-LSK'!$O$5
Name DealNoDefault: '184834 - RELIANCE - BEIRA-LSK'!$O$5
Name DealNoDefault: '186216-RUBIS-BEIRA-LSK'!$O$5
Name DealNoDefault: '187293-LAKE-BEIRA-LSK'!$O$5
Name DealNoDefault: '187296-RUBIS-BEIRA-LSK'!$O$5
Name DealNoDefault: '189084-RUBIS-BEIRA-LSK'!$O$5
Name DealNoDefault: '190261-LAKE-BEIRA-LSK'!$O$5
Name DealNoDefault: '190664-RUBIS-BEIRA-LSK'!$O$5
Name DealNoDefault: '190778-LAKE-BEIRA-LSK'!$O$5
Name DealNoDefault: '191609-RUBIS-BEIRA-LSK'!$O$5
Name DealNoDefault: '191610-RUBIS-BEIRA-LSK'!$O$5
Name DealNoDefault: TEMPLATE!$O$5
Name DealNoDefault: #REF!
Name LaytimeDefault: '184119 - RUBIS - BEIRA-LSK'!$O$6
Name LaytimeDefault: '184182-RUBIS-BEIRA-LSK'!$O$6
Name LaytimeDefault: '184752 - RUBIS - BEIRA-LSK'!$O$6
Name LaytimeDefault: '184834 - RELIANCE - BEIRA-LSK'!$O$6
Name LaytimeDefault: '186216-RUBIS-BEIRA-LSK'!$O$6
Name LaytimeDefault: '187293-LAKE-BEIRA-LSK'!$O$6
Name LaytimeDefault: '187296-RUBIS-BEIRA-LSK'!$O$6
Name LaytimeDefault: '189084-RUBIS-BEIRA-LSK'!$O$6
Name LaytimeDefault: '190261-LAKE-BEIRA-LSK'!$O$6
Name LaytimeDefault: '190664-RUBIS-BEIRA-LSK'!$O$6
Name LaytimeDefault: '190778-LAKE-BEIRA-LSK'!$O$6
Name LaytimeDefault: '191609-RUBIS-BEIRA-LSK'!$O$6
Name LaytimeDefault: '191610-RUBIS-BEIRA-LSK'!$O$6
Name LaytimeDefault: TEMPLATE!$O$6
Name LaytimeDefault: #REF!
Name RateDefault: '184119 - RUBIS - BEIRA-LSK'!$O$7
Name RateDefault: '184182-RUBIS-BEIRA-LSK'!$O$7
Name RateDefault: '184752 - RUBIS - BEIRA-LSK'!$O$7
Name RateDefault: '184834 - RELIANCE - BEIRA-LSK'!$O$7
Name RateDefault: '186216-RUBIS-BEIRA-LSK'!$O$7
Name RateDefault: '187293-LAKE-BEIRA-LSK'!$O$7
Name RateDefault: '187296-RUBIS-BEIRA-LSK'!$O$7
Name RateDefault: '189084-RUBIS-BEIRA-LSK'!$O$7
Name RateDefault: '190261-LAKE-BEIRA-LSK'!$O$7
Name RateDefault: '190664-RUBIS-BEIRA-LSK'!$O$7
Name RateDefault: '190778-LAKE-BEIRA-LSK'!$O$7
Name RateDefault: '191609-RUBIS-BEIRA-LSK'!$O$7
Name RateDefault: '191610-RUBIS-BEIRA-LSK'!$O$7
Name RateDefault: TEMPLATE!$O$7
Name RateDefault: #REF!

Sheet Deals Master
A2: DEALS MASTER
A4: Central register of all demurrage deals • Laytime and rate defaults are pulled from here automatically
A6: Deal No. | B6: Consignee | C6: Route | D6: Loading Port | E6: Destination | F6: Product | G6: Laytime Allowance (days) | H6: Demurrage Rate (USD/day) | I6: Transportation rate (per m3) | J6: Transporter
A7: 183574 | B7: Rubis Energy Zambia | C7: Beira → Lusaka | D7: Beira | E7: Lusaka | F7: PMS | G7: 2 | H7: 250
A8: 184119 | B8: Rubis Energy Zambia | C8: Beira → Lusaka | D8: Beira | E8: Lusaka | F8: PMS | G8: 2 | H8: 250
A9: 184752 | B9: Rubis Energy Zambia | C9: Beira → Lusaka | D9: Beira | E9: Lusaka | F9: PMS | G9: 2 | H9: 250
A10: 184834 | B10: Reliance Energy Zambia | C10: Beira → Lusaka | D10: Beira | E10: Lusaka | F10: PMS | G10: 2 | H10: 250
A11: 185260 | B11: Rubis Energy Zambia | C11: Beira → Lusaka | D11: Beira | E11: Lusaka | F11: PMS | G11: 2 | H11: 250
A12: 185732 | B12: Rubis Energy Zambia | C12: Beira → Lusaka | D12: Beira | E12: Lusaka | F12: PMS | G12: 2 | H12: 250
A13: 186216 | B13: Rubis Energy Zambia | C13: Beira → Lusaka | D13: Beira | E13: Lusaka | F13: PMS | G13: 2 | H13: 250
A14: 186326 | B14: La Grace De Dieu Avec Nous Sarl | C14: Beira → Lusaka | D14: Beira | E14: Lusaka | F14: PMS | G14: 2 | H14: 250
A15: 187293 | B15: Lake Petroleum Zambia | C15: Beira → Lusaka | D15: Beira | E15: Lusaka | F15: PMS | G15: 2 | H15: 250 | I15: 122 | J15: Truckeaze
A16: 187296 | B16: Rubis Energy Zambia | C16: Beira → Lusaka | D16: Beira | E16: Lusaka | F16: PMS | G16: 2 | H16: 250
A17: 189084 | B17: Rubis Energy Zambia | C17: Beira → Lusaka | D17: Beira | E17: Lusaka | F17: PMS | G17: 2 | H17: 250
A18: 190261 | B18: Lake Petroleum Zambia | C18: Beira → Lusaka | D18: Beira | E18: Lusaka | F18: PMS | G18: 2 | H18: 250
A19: 190664 | B19: Rubis Energy Zambia | C19: Beira → Lusaka | D19: Beira | E19: Lusaka | F19: PMS | G19: 2 | H19: 250
A20: 191609 | B20: Rubis Energy Zambia | C20: Beira → Lusaka | D20: Beira | E20: Lusaka | F20: PMS | G20: 2 | H20: 250
A21: 191610 | B21: Rubis Energy Zambia | C21: Beira → Lusaka | D21: Beira | E21: Lusaka | F21: PMS | G21: 2 | H21: 250
A22: 184182 | B22: Rubis Energy Zambia | C22: Beira → Lusaka | D22: Beira | E22: Lusaka | F22: AGO | G22: 2 | H22: 250
A23: 184663 | B23: Reliance Energy Zambia | C23: Beira → Lusaka | D23: Beira | E23: Lusaka | F23: AGO | G23: 2 | H23: 250
A24: 184978 | B24: Reliance Energy Zambia | C24: Beira → Lusaka | D24: Beira | E24: Lusaka | F24: AGO | G24: 2 | H24: 250
A25: 185350 | B25: ARV Energy | C25: Beira → Lusaka | D25: Beira | E25: Lusaka | F25: AGO | G25: 2 | H25: 250
A26: 189548 | B26: La Grace De Dieu Avec Nous Sarl | C26: Beira → Lusaka | D26: Beira | E26: Lusaka | F26: AGO | G26: 2 | H26: 250
A27: 190666 | B27: Rubis Energy Zambia | C27: Beira → Lusaka | D27: Beira | E27: Lusaka | F27: AGO | G27: 2 | H27: 250
A28: 190778 | B28: Lake Petroleum Zambia | C28: Beira → Lusaka | D28: Beira | E28: Lusaka | F28: AGO | G28: 2 | H28: 250 | I28: 135 | J28: Petroda
A29: 190839 | B29: La Grace De Dieu Avec Nous Sarl | C29: Beira → Lusaka | D29: Beira | E29: Lusaka | F29: AGO | G29: 2 | H29: 250
A30: 191685 | B30: Monaluxe | C30: Beira → Lusaka | D30: Beira | E30: Lusaka | F30: AGO | G30: 2 | H30: 250

Sheet Dashboard
B2: DEMURRAGE DASHBOARD
B5: PORTFOLIO SUMMARY
C6: TOTAL DEMURRAGE | F6: ACTIVE DEALS
C7: =G12 -> 6750 | F7: =COUNTA(DealsMaster[Deal No.]) -> 24
B10: Deal No. | C10: Consignee | D10: Route | E10: Total Trips | F10: In Demurrage | G10: Total Demurrage | H10: Avg / Truck
B11: 184119 | C11: =IFERROR(_xlfn.XLOOKUP(B11,DealsMaster[Deal No.],DealsMaster[Consignee]),"") -> Rubis Energy Zambia | D11: =IFERROR(_xlfn.XLOOKUP(B11,DealsMaster[Deal No.],DealsMaster[Route]),"") -> Beira → Lusaka | E11: =COUNTA('184119 - RUBIS - BEIRA-LSK'!A10:A32)-COUNTBLANK('184119 - RUBIS - BEIRA-LSK'!A10:A32) -> 23 | F11: =COUNTIF('184119 - RUBIS - BEIRA-LSK'!O10:O32,"DEMURRAGE") -> 13 | G11: ='184119 - RUBIS - BEIRA-LSK'!C5 -> 6750 | H11: =IF(E11>0,G11/E11,0) -> 293.47826
D12: TOTAL | E12: =SUM(E11:E11) -> 23 | F12: =SUM(F11:F11) -> 13 | G12: =SUM(G11:G11) -> 6750 | H12: =IF(E12>0,G12/E12,0) -> 293.47826
B14: 💡 Add a row per deal sheet. Duplicate _TEMPLATE for new deals, then add a reference row here.

Sheet 184119 - RUBIS - BEIRA-LSK
A1: #VALUE! | C1: =IF(O5=0,"DEMURRAGE CALCULATION — [ENTER DEAL NO. ABOVE]","DEMURRAGE CALCULATION — "&TEXT(O5,"0")&" - "&UPPER(IFERROR(_xlfn.XLOOKUP(O5,DealsMaster[Deal No.],DealsMaster[Consignee]),""))&" - "&UPPER(IFERROR(_xlfn.XLOOKUP(O5,DealsMaster[Deal No.],DealsMaster[Route]),""))) -> DEMURRAGE CALCULATION — 184119 - RUBIS ENERGY ZAMBIA - BEIRA → LUSAKA
C3: KEY METRICS
C4: TOTAL OWED | F4: # IN DEMURRAGE | N4: DEAL DEFAULTS
C5: =SUM('184119 - RUBIS - BEIRA-LSK'!$P$10:$P$32) -> 6750 | F5: =COUNTIF('184119 - RUBIS - BEIRA-LSK'!$O$10:$O$32,"DEMURRAGE")&" / "&COUNTA('184119 - RUBIS - BEIRA-LSK'!$A$10:$A$32) -> 13 / 23 | N5: Deal No. | O5: 184119
N6: Laytime (days) | O6: =IFERROR(_xlfn.XLOOKUP($O$5,DealsMaster[Deal No.],DealsMaster[Laytime Allowance (days)]),0) -> 2
N7: Rate (USD/day) | O7: =IFERROR(_xlfn.XLOOKUP($O$5,DealsMaster[Deal No.],DealsMaster[Demurrage Rate (USD/day)]),0) -> 250
A9: MOCOH Deal No. | B9: Consignee | C9: Date Loaded | D9: Loading Port | E9: Truck No. | F9: Trailer Reg. | G9: Transporter | H9: Driver Name | I9: Destination | J9: Product | K9: Arrival Date at Offloading | L9: Offloaded Date | M9: Total Waiting Days | N9: Laytime Used (days) | O9: Sanity Check | P9: Total Demurrage to Invoice (USD)
A10: =$O$5 -> 184119 | B10: =IFERROR(_xlfn.XLOOKUP($O$5,DealsMaster[Deal No.],DealsMaster[Consignee]),"") -> Rubis Energy Zambia | D10: =IFERROR(_xlfn.XLOOKUP($O$5,DealsMaster[Deal No.],DealsMaster[Loading Port]),"") -> Beira | E10: AEZ6774 | F10: AEZ6933 | G10: Truckeaze | H10: Charuka Antony Denhere | I10: =IFERROR(_xlfn.XLOOKUP($O$5,DealsMaster[Deal No.],DealsMaster[Destination]),"") -> Lusaka | J10: =IFERROR(_xlfn.XLOOKUP($O$5,DealsMaster[Deal No.],DealsMaster[Product]),"") -> PMS | K10: 46003 | L10: 46004 | M10: =IF(OR(K10="",L10=""),"",L10-K10) -> 1 | N10: =$O$6 -> 2 | O10: =IF(AND(C10<>"",K10<>"",K10<C10),"⚠ Arrival < Loaded",IF(AND(K10<>"",L10<>"",L10<K10),"⚠ Offloaded < Arrival",IF(M10="","",IF(M10>N10,"DEMURRAGE","OK")))) -> OK | P10: =IF(M10="","",MAX(0,M10-N10)*$O$7) -> 0
A11: =$O$5 -> 184119 | B11: =IFERROR(_xlfn.XLOOKUP($O$5,DealsMaster[Deal No.],DealsMaster[Consignee]),"") -> Rubis Energy Zambia | D11: =IFERROR(_xlfn.XLOOKUP($O$5,DealsMaster[Deal No.],DealsMaster[Loading Port]),"") -> Beira | E11: AEZ6774 | F11: AEZ6933 | G11: Truckeaze | H11: Charuka Antony Denhere | I11: =IFERROR(_xlfn.XLOOKUP($O$5,DealsMaster[Deal No.],DealsMaster[Destination]),"") -> Lusaka | J11: =IFERROR(_xlfn.XLOOKUP($O$5,DealsMaster[Deal No.],DealsMaster[Product]),"") -> PMS | K11: 46002 | L11: 46007 | M11: =IF(OR(K11="",L11=""),"",L11-K11) -> 5 | N11: =$O$6 -> 2 | O11: =IF(AND(C11<>"",K11<>"",K11<C11),"⚠ Arrival < Loaded",IF(AND(K11<>"",L11<>"",L11<K11),"⚠ Offloaded < Arrival",IF(M11="","",IF(M11>N11,"DEMURRAGE","OK")))) -> DEMURRAGE | P11: =IF(M11="","",MAX(0,M11-N11)*$O$7) -> 750
A12: =$O$5 -> 184119 | B12: =IFERROR(_xlfn.XLOOKUP($O$5,DealsMaster[Deal No.],DealsMaster[Consignee]),"") -> Rubis Energy Zambia | D12: =IFERROR(_xlfn.XLOOKUP($O$5,DealsMaster[Deal No.],DealsMaster[Loading Port]),"") -> Beira | E12: AEZ6774 | F12: AEZ6933 | G12: Truckeaze | H12: Charuka Antony Denhere | I12: =IFERROR(_xlfn.XLOOKUP($O$5,DealsMaster[Deal No.],DealsMaster[Destination]),"") -> Lusaka | J12: =IFERROR(_xlfn.XLOOKUP($O$5,DealsMaster[Deal No.],DealsMaster[Product]),"") -> PMS | K12: 46003 | L12: 46004 | M12: =IF(OR(K12="",L12=""),"",L12-K12) -> 1 | N12: =$O$6 -> 2 | O12: =IF(AND(C12<>"",K12<>"",K12<C12),"⚠ Arrival < Loaded",IF(AND(K12<>"",L12<>"",L12<K12),"⚠ Offloaded < Arrival",IF(M12="","",IF(M12>N12,"DEMURRAGE","OK")))) -> OK | P12: =IF(M12="","",MAX(0,M12-N12)*$O$7) -> 0
A13: =$O$5 -> 184119 | B13: =IFERROR(_xlfn.XLOOKUP($O$5,DealsMaster[Deal No.],DealsMaster[Consignee]),"") -> Rubis Energy Zambia | D13: =IFERROR(_xlfn.XLOOKUP($O$5,DealsMaster[Deal No.],DealsMaster[Loading Port]),"") -> Beira | E13: AEZ6774 | F13: AEZ6933 | G13: Truckeaze | H13: Charuka Antony Denhere | I13: =IFERROR(_xlfn.XLOOKUP($O$5,DealsMaster[Deal No.],DealsMaster[Destination]),"") -> Lusaka | J13: =IFERROR(_xlfn.XLOOKUP($O$5,DealsMaster[Deal No.],DealsMaster[Product]),"") -> PMS | K13: 46011 | L13: 46015 | M13: =IF(OR(K13="",L13=""),"",L13-K13) -> 4 | N13: =$O$6 -> 2 | O13: =IF(AND(C13<>"",K13<>"",K13<C13),"⚠ Arrival < Loaded",IF(AND(K13<>"",L13<>"",L13<K13),"⚠ Offloaded < Arrival",IF(M13="","",IF(M13>N13,"DEMURRAGE","OK")))) -> DEMURRAGE | P13: =IF(M13="","",MAX(0,M13-N13)*$O$7) -> 500
A14: =$O$5 -> 184119 | B14: =IFERROR(_xlfn.XLOOKUP($O$5,DealsMaster[Deal No.],DealsMaster[Consignee]),"") -> Rubis Energy Zambia | D14: =IFERROR(_xlfn.XLOOKUP($O$5,DealsMaster[Deal No.],DealsMaster[Loading Port]),"") -> Beira | E14: AEZ6774 | F14: AEZ6933 | G14: Truckeaze | H14: Charuka Antony Denhere | I14: =IFERROR(_xlfn.XLOOKUP($O$5,DealsMaster[Deal No.],DealsMaster[Destination]),"") -> Lusaka | J14: =IFERROR(_xlfn.XLOOKUP($O$5,DealsMaster[Deal No.],DealsMaster[Product]),"") -> PMS | K14: 46010 | L14: 46011 | M14: =IF(OR(K14="",L14=""),"",L14-K14) -> 1 | N14: =$O$6 -> 2 | O14: =IF(AND(C14<>"",K14<>"",K14<C14),"⚠ Arrival < Loaded",IF(AND(K14<>"",L14<>"",L14<K14),"⚠ Offloaded < Arrival",IF(M14="","",IF(M14>N14,"DEMURRAGE","OK")))) -> OK | P14: =IF(M14="","",MAX(0,M14-N14)*$O$7) -> 0
A15: =$O$5 -> 184119 | B15: =IFERROR(_xlfn.XLOOKUP($O$5,DealsMaster[Deal No.],DealsMaster[Consignee]),"") -> Rubis Energy Zambia | D15: =IFERROR(_xlfn.XLOOKUP($O$5,DealsMaster[Deal No.],DealsMaster[Loading Port]),"") -> Beira | E15: AEZ6774 | F15: AEZ6933 | G15: Truckeaze | H15: Charuka Antony Denhere | I15: =IFERROR(_xlfn.XLOOKUP($O$5,DealsMaster[Deal No.],DealsMaster[Destination]),"") -> Lusaka | J15: =IFERROR(_xlfn.XLOOKUP($O$5,DealsMaster[Deal No.],DealsMaster[Product]),"") -> PMS | K15: 46002 | L15: 46007 | M15: =IF(OR(K15="",L15=""),"",L15-K15) -> 5 | N15: =$O$6 -> 2 | O15: =IF(AND(C15<>"",K15<>"",K15<C15),"⚠ Arrival < Loaded",IF(AND(K15<>"",L15<>"",L15<K15),"⚠ Offloaded < Arrival",IF(M15="","",IF(M15>N15,"DEMURRAGE","OK")))) -> DEMURRAGE | P15: =IF(M15="","",MAX(0,M15-N15)*$O$7) -> 750
A16: =$O$5 -> 184119 | B16: =IFERROR(_xlfn.XLOOKUP($O$5,DealsMaster[Deal No.],DealsMaster[Consignee]),"") -> Rubis Energy Zambia | D16: =IFERROR(_xlfn.XLOOKUP($O$5,DealsMaster[Deal No.],DealsMaster[Loading Port]),"") -> Beira | E16: AEZ6774 | F16: AEZ6933 | G16: Truckeaze | H16: Charuka Antony Denhere | I16: =IFERROR(_xlfn.XLOOKUP($O$5,DealsMaster[Deal No.],DealsMaster[Destination]),"") -> Lusaka | J16: =IFERROR(_xlfn.XLOOKUP($O$5,DealsMaster[Deal No.],DealsMaster[Product]),"") -> PMS | K16: 46010 | L16: 46011 | M16: =IF(OR(K16="",L16=""),"",L16-K16) -> 1 | N16: =$O$6 -> 2 | O16: =IF(AND(C16<>"",K16<>"",K16<C16),"⚠ Arrival < Loaded",IF(AND(K16<>"",L16<>"",L16<K16),"⚠ Offloaded < Arrival",IF(M16="","",IF(M16>N16,"DEMURRAGE","OK")))) -> OK | P16: =IF(M16="","",MAX(0,M16-N16)*$O$7) -> 0
A17: =$O$5 -> 184119 | B17: =IFERROR(_xlfn.XLOOKUP($O$5,DealsMaster[Deal No.],DealsMaster[Consignee]),"") -> Rubis Energy Zambia | D17: =IFERROR(_xlfn.XLOOKUP($O$5,DealsMaster[Deal No.],DealsMaster[Loading Port]),"") -> Beira | E17: AEZ6774 | F17: AEZ6933 | G17: Truckeaze | H17: Charuka Antony Denhere | I17: =IFERROR(_xlfn.XLOOKUP($O$5,DealsMaster[Deal No.],DealsMaster[Destination]),"") -> Lusaka | J17: =IFERROR(_xlfn.XLOOKUP($O$5,DealsMaster[Deal No.],DealsMaster[Product]),"") -> PMS | K17: 46008 | L17: 46009 | M17: =IF(OR(K17="",L17=""),"",L17-K17) -> 1 | N17: =$O$6 -> 2 | O17: =IF(AND(C17<>"",K17<>"",K17<C17),"⚠ Arrival < Loaded",IF(AND(K17<>"",L17<>"",L17<K17),"⚠ Offloaded < Arrival",IF(M17="","",IF(M17>N17,"DEMURRAGE","OK")))) -> OK | P17: =IF(M17="","",MAX(0,M17-N17)*$O$7) -> 0
A18: =$O$5 -> 184119 | B18: =IFERROR(_xlfn.XLOOKUP($O$5,DealsMaster[Deal No.],DealsMaster[Consignee]),"") -> Rubis Energy Zambia | D18: =IFERROR(_xlfn.XLOOKUP($O$5,DealsMaster[Deal No.],DealsMaster[Loading Port]),"") -> Beira | E18: AEZ6774 | F18: AEZ6933 | G18: Truckeaze | H18: Charuka Antony Denhere | I18: =IFERROR(_xlfn.XLOOKUP($O$5,DealsMaster[Deal No.],DealsMaster[Destination]),"") -> Lusaka | J18: =IFERROR(_xlfn.XLOOKUP($O$5,DealsMaster[Deal No.],DealsMaster[Product]),"") -> PMS | K18: 46002 | L18: 46007 | M18: =IF(OR(K18="",L18=""),"",L18-K18) -> 5 | N18: =$O$6 -> 2 | O18: =IF(AND(C18<>"",K18<>"",K18<C18),"⚠ Arrival < Loaded",IF(AND(K18<>"",L18<>"",L18<K18),"⚠ Offloaded < Arrival",IF(M18="","",IF(M18>N18,"DEMURRAGE","OK")))) -> DEMURRAGE | P18: =IF(M18="","",MAX(0,M18-N18)*$O$7) -> 750
A19: =$O$5 -> 184119 | B19: =IFERROR(_xlfn.XLOOKUP($O$5,DealsMaster[Deal No.],DealsMaster[Consignee]),"") -> Rubis Energy Zambia | D19: =IFERROR(_xlfn.XLOOKUP($O$5,DealsMaster[Deal No.],DealsMaster[Loading Port]),"") -> Beira | E19: AEZ6774 | F19: AEZ6933 | G19: Truckeaze | H19: Charuka Antony Denhere | I19: =IFERROR(_xlfn.XLOOKUP($O$5,DealsMaster[Deal No.],DealsMaster[Destination]),"") -> Lusaka | J19: =IFERROR(_xlfn.XLOOKUP($O$5,DealsMaster[Deal No.],DealsMaster[Product]),"") -> PMS | K19: 46003 | L19: 46004 | M19: =IF(OR(K19="",L19=""),"",L19-K19) -> 1 | N19: =$O$6 -> 2 | O19: =IF(AND(C19<>"",K19<>"",K19<C19),"⚠ Arrival < Loaded",IF(AND(K19<>"",L19<>"",L19<K19),"⚠ Offloaded < Arrival",IF(M19="","",IF(M19>N19,"DEMURRAGE","OK")))) -> OK | P19: =IF(M19="","",MAX(0,M19-N19)*$O$7) -> 0
A20: =$O$5 -> 184119 | B20: =IFERROR(_xlfn.XLOOKUP($O$5,DealsMaster[Deal No.],DealsMaster[Consignee]),"") -> Rubis Energy Zambia | D20: =IFERROR(_xlfn.XLOOKUP($O$5,DealsMaster[Deal No.],DealsMaster[Loading Port]),"") -> Beira | E20: AEZ6774 | F20: AEZ6933 | G20: Truckeaze | H20: Charuka Antony Denhere | I20: =IFERROR(_xlfn.XLOOKUP($O$5,DealsMaster[Deal No.],DealsMaster[Destination]),"") -> Lusaka | J20: =IFERROR(_xlfn.XLOOKUP($O$5,DealsMaster[Deal No.],DealsMaster[Product]),"") -> PMS | K20: 46002 | L20: 46007 | M20: =IF(OR(K20="",L20=""),"",L20-K20) -> 5 | N20: =$O$6 -> 2 | O20: =IF(AND(C20<>"",K20<>"",K20<C20),"⚠ Arrival < Loaded",IF(AND(K20<>"",L20<>"",L20<K20),"⚠ Offloaded < Arrival",IF(M20="","",IF(M20>N20,"DEMURRAGE","OK")))) -> DEMURRAGE | P20: =IF(M20="","",MAX(0,M20-N20)*$O$7) -> 750
A21: =$O$5 -> 184119 | B21: =IFERROR(_xlfn.XLOOKUP($O$5,DealsMaster[Deal No.],DealsMaster[Consignee]),"") -> Rubis Energy Zambia | D21: =IFERROR(_xlfn.XLOOKUP($O$5,DealsMaster[Deal No.],DealsMaster[Loading Port]),"") -> Beira | E21: AEZ6774 | F21: AEZ6933 | G21: Truckeaze | H21: Charuka Antony Denhere | I21: =IFERROR(_xlfn.XLOOKUP($O$5,DealsMaster[Deal No.],DealsMaster[Destination]),"") -> Lusaka | J21: =IFERROR(_xlfn.XLOOKUP($O$5,DealsMaster[Deal No.],DealsMaster[Product]),"") -> PMS | K21: 46002 | L21: 46007 | M21: =IF(OR(K21="",L21=""),"",L21-K21) -> 5 | N21: =$O$6 -> 2 | O21: =IF(AND(C21<>"",K21<>"",K21<C21),"⚠ Arrival < Loaded",IF(AND(K21<>"",L21<>"",L21<K21),"⚠ Offloaded < Arrival",IF(M21="","",IF(M21>N21,"DEMURRAGE","OK")))) -> DEMURRAGE | P21: =IF(M21="","",MAX(0,M21-N21)*$O$7) -> 750
... A32: =$O$5 -> 184119 | B32: =IFERROR(_xlfn.XLOOKUP($O$5,DealsMaster[Deal No.],DealsMaster[Consignee]),"") -> Rubis Energy Zambia | D32: =IFERROR(_xlfn.XLOOKUP($O$5,DealsMaster[Deal No.],DealsMaster[Loading Port]),"") -> Beira | E32: AEZ6774 | F32: AEZ6933 | G32: Truckeaze | H32: Charuka Antony Denhere | I32: =IFERROR(_xlfn.XLOOKUP($O$5,DealsMaster[Deal No.],DealsMaster[Destination]),"") -> Lusaka | J32: =IFERROR(_xlfn.XLOOKUP($O$5,DealsMaster[Deal No.],DealsMaster[Product]),"") -> PMS | K32: 46001 | L32: 46003 | M32: =IF(OR(K32="",L32=""),"",L32-K32) -> 2 | N32: =$O$6 -> 2 | O32: =IF(AND(C32<>"",K32<>"",K32<C32),"⚠ Arrival < Loaded",IF(AND(K32<>"",L32<>"",L32<K32),"⚠ Offloaded < Arrival",IF(M32="","",IF(M32>N32,"DEMURRAGE","OK")))) -> OK | P32: =IF(M32="","",MAX(0,M32-N32)*$O$7) -> 0
A33: TOTAL | P33: =SUBTOTAL(109,P10:P32) -> 6750

Sheet 184752 - RUBIS - BEIRA-LSK
C1: =IF(O5=0,"DEMURRAGE CALCULATION — [ENTER DEAL NO. ABOVE]","DEMURRAGE CALCULATION — "&TEXT(O5,"0")&" - "&UPPER(IFERROR(_xlfn.XLOOKUP(O5,DealsMaster[Deal No.],DealsMaster[Consignee]),""))&" - "&UPPER(IFERROR(_xlfn.XLOOKUP(O5,DealsMaster[Deal No.],DealsMaster[Route]),""))) -> DEMURRAGE CALCULATION — 184752 - RUBIS ENERGY ZAMBIA - BEIRA → LUSAKA
C3: KEY METRICS
C4: TOTAL OWED | F4: # IN DEMURRAGE | N4: DEAL DEFAULTS
C5: =SUM('184752 - RUBIS - BEIRA-LSK'!$P$10:$P$31) -> 5500 | F5: =COUNTIF('184752 - RUBIS - BEIRA-LSK'!$O$10:$O$31,"DEMURRAGE")&" / "&COUNTA('184752 - RUBIS - BEIRA-LSK'!$A$10:$A$31) -> 10 / 22 | N5: Deal No. | O5: 184752
N6: Laytime (days) | O6: =IFERROR(_xlfn.XLOOKUP($O$5,DealsMaster[Deal No.],DealsMaster[Laytime Allowance (days)]),0) -> 2
N7: Rate (USD/day) | O7: =IFERROR(_xlfn.XLOOKUP($O$5,DealsMaster[Deal No.],DealsMaster[Demurrage Rate (USD/day)]),0) -> 250
A8: HOW TO USE: | B8: 1️⃣ Enter Deal No. in the gold box above → 2️⃣ Fill in truck details (columns C–L) row by row → 3️⃣ Demurrage calculates automatically → 4️⃣ Rename the sheet tab when done
A9: MOCOH Deal No. | B9: Consignee | C9: Date Loaded | D9: Loading Port | E9: Truck No. | F9: Trailer Reg. | G9: Transporter | H9: Driver Name | I9: Destination | J9: Product | K9: Arrival Date at Offloading | L9: Offloaded Date | M9: Total Waiting Days | N9: Laytime Used (days) | O9: Sanity Check | P9: Total Demurrage to Invoice (USD)
A10: =$O$5 -> 184752 | B10: =IFERROR(_xlfn.XLOOKUP($O$5,DealsMaster[Deal No.],DealsMaster[Consignee]),"") -> Rubis Energy Zambia | C10: 46006 | D10: =IFERROR(_xlfn.XLOOKUP($O$5,DealsMaster[Deal No.],DealsMaster[Loading Port]),"") -> Beira | E10: AHN 716 MP | F10: AJ 041 MC | G10: WHC | H10: Average Chitengwa | I10: =IFERROR(_xlfn.XLOOKUP($O$5,DealsMaster[Deal No.],DealsMaster[Destination]),"") -> Lusaka | J10: =IFERROR(_xlfn.XLOOKUP($O$5,DealsMaster[Deal No.],DealsMaster[Product]),"") -> PMS | K10: 46011 | L10: 46015 | M10: =IF(OR(K10="",L10=""),"",L10-K10) -> 4 | N10: =$O$6 -> 2 | O10: =IF(AND(C10<>"",K10<>"",K10<C10),"⚠ Arrival < Loaded",IF(AND(K10<>"",L10<>"",L10<K10),"⚠ Offloaded < Arrival",IF(M10="","",IF(M10>N10,"DEMURRAGE","OK")))) -> DEMURRAGE | P10: =IF(M10="","",MAX(0,M10-N10)*$O$7) -> 500
A11: =$O$5 -> 184752 | B11: =IFERROR(_xlfn.XLOOKUP($O$5,DealsMaster[Deal No.],DealsMaster[Consignee]),"") -> Rubis Energy Zambia | C11: 46006 | D11: =IFERROR(_xlfn.XLOOKUP($O$5,DealsMaster[Deal No.],DealsMaster[Loading Port]),"") -> Beira | E11: AFW 378 MP | F11: AE 731 MC | G11: WHC | H11: Kangai Tafirenyika | I11: =IFERROR(_xlfn.XLOOKUP($O$5,DealsMaster[Deal No.],DealsMaster[Destination]),"") -> Lusaka | J11: =IFERROR(_xlfn.XLOOKUP($O$5,DealsMaster[Deal No.],DealsMaster[Product]),"") -> PMS | K11: 46011 | L11: 46015 | M11: =IF(OR(K11="",L11=""),"",L11-K11) -> 4 | N11: =$O$6 -> 2 | O11: =IF(AND(C11<>"",K11<>"",K11<C11),"⚠ Arrival < Loaded",IF(AND(K11<>"",L11<>"",L11<K11),"⚠ Offloaded < Arrival",IF(M11="","",IF(M11>N11,"DEMURRAGE","OK")))) -> DEMURRAGE | P11: =IF(M11="","",MAX(0,M11-N11)*$O$7) -> 500
A12: =$O$5 -> 184752 | B12: =IFERROR(_xlfn.XLOOKUP($O$5,DealsMaster[Deal No.],DealsMaster[Consignee]),"") -> Rubis Energy Zambia | C12: 46006 | D12: =IFERROR(_xlfn.XLOOKUP($O$5,DealsMaster[Deal No.],DealsMaster[Loading Port]),"") -> Beira | E12: AIB 049 MC | F12: AF 715 MC | G12: WHC | H12: Kumirai Krispen | I12: =IFERROR(_xlfn.XLOOKUP($O$5,DealsMaster[Deal No.],DealsMaster[Destination]),"") -> Lusaka | J12: =IFERROR(_xlfn.XLOOKUP($O$5,DealsMaster[Deal No.],DealsMaster[Product]),"") -> PMS | K12: 46011 | L12: 46015 | M12: =IF(OR(K12="",L12=""),"",L12-K12) -> 4 | N12: =$O$6 -> 2 | O12: =IF(AND(C12<>"",K12<>"",K12<C12),"⚠ Arrival < Loaded",IF(AND(K12<>"",L12<>"",L12<K12),"⚠ Offloaded < Arrival",IF(M12="","",IF(M12>N12,"DEMURRAGE","OK")))) -> DEMURRAGE | P12: =IF(M12="","",MAX(0,M12-N12)*$O$7) -> 500
A13: =$O$5 -> 184752 | B13: =IFERROR(_xlfn.XLOOKUP($O$5,DealsMaster[Deal No.],DealsMaster[Consignee]),"") -> Rubis Energy Zambia | C13: 46006 | D13: =IFERROR(_xlfn.XLOOKUP($O$5,DealsMaster[Deal No.],DealsMaster[Loading Port]),"") -> Beira | E13: AGU 496 MP | F13: AF 738 MC | G13: WHC | H13: Nhamo Mukwekwerere | I13: =IFERROR(_xlfn.XLOOKUP($O$5,DealsMaster[Deal No.],DealsMaster[Destination]),"") -> Lusaka | J13: =IFERROR(_xlfn.XLOOKUP($O$5,DealsMaster[Deal No.],DealsMaster[Product]),"") -> PMS | K13: 46011 | L13: 46015 | M13: =IF(OR(K13="",L13=""),"",L13-K13) -> 4 | N13: =$O$6 -> 2 | O13: =IF(AND(C13<>"",K13<>"",K13<C13),"⚠ Arrival < Loaded",IF(AND(K13<>"",L13<>"",L13<K13),"⚠ Offloaded < Arrival",IF(M13="","",IF(M13>N13,"DEMURRAGE","OK")))) -> DEMURRAGE | P13: =IF(M13="","",MAX(0,M13-N13)*$O$7) -> 500
A14: =$O$5 -> 184752 | B14: =IFERROR(_xlfn.XLOOKUP($O$5,DealsMaster[Deal No.],DealsMaster[Consignee]),"") -> Rubis Energy Zambia | C14: 46006 | D14: =IFERROR(_xlfn.XLOOKUP($O$5,DealsMaster[Deal No.],DealsMaster[Loading Port]),"") -> Beira | E14: AJJ 602 MP | F14: AF 699 MC | G14: WHC | H14: Hestings Banda | I14: =IFERROR(_xlfn.XLOOKUP($O$5,DealsMaster[Deal No.],DealsMaster[Destination]),"") -> Lusaka | J14: =IFERROR(_xlfn.XLOOKUP($O$5,DealsMaster[Deal No.],DealsMaster[Product]),"") -> PMS | K14: 46011 | L14: 46015 | M14: =IF(OR(K14="",L14=""),"",L14-K14) -> 4 | N14: =$O$6 -> 2 | O14: =IF(AND(C14<>"",K14<>"",K14<C14),"⚠ Arrival < Loaded",IF(AND(K14<>"",L14<>"",L14<K14),"⚠ Offloaded < Arrival",IF(M14="","",IF(M14>N14,"DEMURRAGE","OK")))) -> DEMURRAGE | P14: =IF(M14="","",MAX(0,M14-N14)*$O$7) -> 500
A15: =$O$5 -> 184752 | B15: =IFERROR(_xlfn.XLOOKUP($O$5,DealsMaster[Deal No.],DealsMaster[Consignee]),"") -> Rubis Energy Zambia | C15: 46006 | D15: =IFERROR(_xlfn.XLOOKUP($O$5,DealsMaster[Deal No.],DealsMaster[Loading Port]),"") -> Beira | E15: AFV 439 MP | F15: AE 760 MC | G15: WHC | H15: Adelino Silira | I15: =IFERROR(_xlfn.XLOOKUP($O$5,DealsMaster[Deal No.],DealsMaster[Destination]),"") -> Lusaka | J15: =IFERROR(_xlfn.XLOOKUP($O$5,DealsMaster[Deal No.],DealsMaster[Product]),"") -> PMS | K15: 46011 | L15: 46015 | M15: =IF(OR(K15="",L15=""),"",L15-K15) -> 4 | N15: =$O$6 -> 2 | O15: =IF(AND(C15<>"",K15<>"",K15<C15),"⚠ Arrival < Loaded",IF(AND(K15<>"",L15<>"",L15<K15),"⚠ Offloaded < Arrival",IF(M15="","",IF(M15>N15,"DEMURRAGE","OK")))) -> DEMURRAGE | P15: =IF(M15="","",MAX(0,M15-N15)*$O$7) -> 500
A16: =$O$5 -> 184752 | B16: =IFERROR(_xlfn.XLOOKUP($O$5,DealsMaster[Deal No.],DealsMaster[Consignee]),"") -> Rubis Energy Zambia | C16: 46021 | D16: =IFERROR(_xlfn.XLOOKUP($O$5,DealsMaster[Deal No.],DealsMaster[Loading Port]),"") -> Beira | E16: AIB 049 MC | F16: AF 715 MC | G16: WHC | H16: Kumirai Krispen | I16: =IFERROR(_xlfn.XLOOKUP($O$5,DealsMaster[Deal No.],DealsMaster[Destination]),"") -> Lusaka | J16: =IFERROR(_xlfn.XLOOKUP($O$5,DealsMaster[Deal No.],DealsMaster[Product]),"") -> PMS | K16: 46030 | L16: 46035 | M16: =IF(OR(K16="",L16=""),"",L16-K16) -> 5 | N16: =$O$6 -> 2 | O16: =IF(AND(C16<>"",K16<>"",K16<C16),"⚠ Arrival < Loaded",IF(AND(K16<>"",L16<>"",L16<K16),"⚠ Offloaded < Arrival",IF(M16="","",IF(M16>N16,"DEMURRAGE","OK")))) -> DEMURRAGE | P16: =IF(M16="","",MAX(0,M16-N16)*$O$7) -> 750
A17: =$O$5 -> 184752 | B17: =IFERROR(_xlfn.XLOOKUP($O$5,DealsMaster[Deal No.],DealsMaster[Consignee]),"") -> Rubis Energy Zambia | C17: 46021 | D17: =IFERROR(_xlfn.XLOOKUP($O$5,DealsMaster[Deal No.],DealsMaster[Loading Port]),"") -> Beira | E17: AFV 439 MP | F17: AE 760 MC | G17: WHC | H17: Adelino Silira | I17: =IFERROR(_xlfn.XLOOKUP($O$5,DealsMaster[Deal No.],DealsMaster[Destination]),"") -> Lusaka | J17: =IFERROR(_xlfn.XLOOKUP($O$5,DealsMaster[Deal No.],DealsMaster[Product]),"") -> PMS | K17: 46030 | L17: 46034 | M17: =IF(OR(K17="",L17=""),"",L17-K17) -> 4 | N17: =$O$6 -> 2 | O17: =IF(AND(C17<>"",K17<>"",K17<C17),"⚠ Arrival < Loaded",IF(AND(K17<>"",L17<>"",L17<K17),"⚠ Offloaded < Arrival",IF(M17="","",IF(M17>N17,"DEMURRAGE","OK")))) -> DEMURRAGE | P17: =IF(M17="","",MAX(0,M17-N17)*$O$7) -> 500
A18: =$O$5 -> 184752 | B18: =IFERROR(_xlfn.XLOOKUP($O$5,DealsMaster[Deal No.],DealsMaster[Consignee]),"") -> Rubis Energy Zambia | C18: 46021 | D18: =IFERROR(_xlfn.XLOOKUP($O$5,DealsMaster[Deal No.],DealsMaster[Loading Port]),"") -> Beira | E18: AIQ 955 MP | F18: AJ 042 MC | G18: WHC | H18: Maxwell Shamu | I18: =IFERROR(_xlfn.XLOOKUP($O$5,DealsMaster[Deal No.],DealsMaster[Destination]),"") -> Lusaka | J18: =IFERROR(_xlfn.XLOOKUP($O$5,DealsMaster[Deal No.],DealsMaster[Product]),"") -> PMS | K18: 46030 | L18: 46035 | M18: =IF(OR(K18="",L18=""),"",L18-K18) -> 5 | N18: =$O$6 -> 2 | O18: =IF(AND(C18<>"",K18<>"",K18<C18),"⚠ Arrival < Loaded",IF(AND(K18<>"",L18<>"",L18<K18),"⚠ Offloaded < Arrival",IF(M18="","",IF(M18>N18,"DEMURRAGE","OK")))) -> DEMURRAGE | P18: =IF(M18="","",MAX(0,M18-N18)*$O$7) -> 750
A19: =$O$5 -> 184752 | B19: =IFERROR(_xlfn.XLOOKUP($O$5,DealsMaster[Deal No.],DealsMaster[Consignee]),"") -> Rubis Energy Zambia | C19: 46021 | D19: =IFERROR(_xlfn.XLOOKUP($O$5,DealsMaster[Deal No.],DealsMaster[Loading Port]),"") -> Beira | E19: AAX 014 SF | F19: AA 475 MC | G19: WHC | H19: Clayton Kamudzeya | I19: =IFERROR(_xlfn.XLOOKUP($O$5,DealsMaster[Deal No.],DealsMaster[Destination]),"") -> Lusaka | J19: =IFERROR(_xlfn.XLOOKUP($O$5,DealsMaster[Deal No.],DealsMaster[Product]),"") -> PMS | K19: 46030 | L19: 46034 | M19: =IF(OR(K19="",L19=""),"",L19-K19) -> 4 | N19: =$O$6 -> 2 | O19: =IF(AND(C19<>"",K19<>"",K19<C19),"⚠ Arrival < Loaded",IF(AND(K19<>"",L19<>"",L19<K19),"⚠ Offloaded < Arrival",IF(M19="","",IF(M19>N19,"DEMURRAGE","OK")))) -> DEMURRAGE | P19: =IF(M19="","",MAX(0,M19-N19)*$O$7) -> 500
A20: =$O$5 -> 184752 | B20: =IFERROR(_xlfn.XLOOKUP($O$5,DealsMaster[Deal No.],DealsMaster[Consignee]),"") -> Rubis Energy Zambia | D20: =IFERROR(_xlfn.XLOOKUP($O$5,DealsMaster[Deal No.],DealsMaster[Loading Port]),"") -> Beira | I20: =IFERROR(_xlfn.XLOOKUP($O$5,DealsMaster[Deal No.],DealsMaster[Destination]),"") -> Lusaka | J20: =IFERROR(_xlfn.XLOOKUP($O$5,DealsMaster[Deal No.],DealsMaster[Product]),"") -> PMS | M20: =IF(OR(K20="",L20=""),"",L20-K20) | N20: =$O$6 -> 2 | O20: =IF(AND(C20<>"",K20<>"",K20<C20),"⚠ Arrival < Loaded",IF(AND(K20<>"",L20<>"",L20<K20),"⚠ Offloaded < Arrival",IF(M20="","",IF(M20>N20,"DEMURRAGE","OK")))) | P20: =IF(M20="","",MAX(0,M20-N20)*$O$7)
A21: =$O$5 -> 184752 | B21: =IFERROR(_xlfn.XLOOKUP($O$5,DealsMaster[Deal No.],DealsMaster[Consignee]),"") -> Rubis Energy Zambia | D21: =IFERROR(_xlfn.XLOOKUP($O$5,DealsMaster[Deal No.],DealsMaster[Loading Port]),"") -> Beira | I21: =IFERROR(_xlfn.XLOOKUP($O$5,DealsMaster[Deal No.],DealsMaster[Destination]),"") -> Lusaka | J21: =IFERROR(_xlfn.XLOOKUP($O$5,DealsMaster[Deal No.],DealsMaster[Product]),"") -> PMS | M21: =IF(OR(K21="",L21=""),"",L21-K21) | N21: =$O$6 -> 2 | O21: =IF(AND(C21<>"",K21<>"",K21<C21),"⚠ Arrival < Loaded",IF(AND(K21<>"",L21<>"",L21<K21),"⚠ Offloaded < Arrival",IF(M21="","",IF(M21>N21,"DEMURRAGE","OK")))) | P21: =IF(M21="","",MAX(0,M21-N21)*$O$7)
A22: =$O$5 -> 184752 | B22: =IFERROR(_xlfn.XLOOKUP($O$5,DealsMaster[Deal No.],DealsMaster[Consignee]),"") -> Rubis Energy Zambia | D22: =IFERROR(_xlfn.XLOOKUP($O$5,DealsMaster[Deal No.],DealsMaster[Loading Port]),"") -> Beira | I22: =IFERROR(_xlfn.XLOOKUP($O$5,DealsMaster[Deal No.],DealsMaster[Destination]),"") -> Lusaka | J22: =IFERROR(_xlfn.XLOOKUP($O$5,DealsMaster[Deal No.],DealsMaster[Product]),"") -> PMS | M22: =IF(OR(K22="",L22=""),"",L22-K22) | N22: =$O$6 -> 2 | O22: =IF(AND(C22<>"",K22<>"",K22<C22),"⚠ Arrival < Loaded",IF(AND(K22<>"",L22<>"",L22<K22),"⚠ Offloaded < Arrival",IF(M22="","",IF(M22>N22,"DEMURRAGE","OK")))) | P22: =IF(M22="","",MAX(0,M22-N22)*$O$7)
A23: =$O$5 -> 184752 | B23: =IFERROR(_xlfn.XLOOKUP($O$5,DealsMaster[Deal No.],DealsMaster[Consignee]),"") -> Rubis Energy Zambia | D23: =IFERROR(_xlfn.XLOOKUP($O$5,DealsMaster[Deal No.],DealsMaster[Loading Port]),"") -> Beira | I23: =IFERROR(_xlfn.XLOOKUP($O$5,DealsMaster[Deal No.],DealsMaster[Destination]),"") -> Lusaka | J23: =IFERROR(_xlfn.XLOOKUP($O$5,DealsMaster[Deal No.],DealsMaster[Product]),"") -> PMS | M23: =IF(OR(K23="",L23=""),"",L23-K23) | N23: =$O$6 -> 2 | O23: =IF(AND(C23<>"",K23<>"",K23<C23),"⚠ Arrival < Loaded",IF(AND(K23<>"",L23<>"",L23<K23),"⚠ Offloaded < Arrival",IF(M23="","",IF(M23>N23,"DEMURRAGE","OK")))) | P23: =IF(M23="","",MAX(0,M23-N23)*$O$7)
A24: =$O$5 -> 184752 | B24: =IFERROR(_xlfn.XLOOKUP($O$5,DealsMaster[Deal No.],DealsMaster[Consignee]),"") -> Rubis Energy Zambia | D24: =IFERROR(_xlfn.XLOOKUP($O$5,DealsMaster[Deal No.],DealsMaster[Loading Port]),"") -> Beira | I24: =IFERROR(_xlfn.XLOOKUP($O$5,DealsMaster[Deal No.],DealsMaster[Destination]),"") -> Lusaka | J24: =IFERROR(_xlfn.XLOOKUP($O$5,DealsMaster[Deal No.],DealsMaster[Product]),"") -> PMS | M24: =IF(OR(K24="",L24=""),"",L24-K24) | N24: =$O$6 -> 2 | O24: =IF(AND(C24<>"",K24<>"",K24<C24),"⚠ Arrival < Loaded",IF(AND(K24<>"",L24<>"",L24<K24),"⚠ Offloaded < Arrival",IF(M24="","",IF(M24>N24,"DEMURRAGE","OK")))) | P24: =IF(M24="","",MAX(0,M24-N24)*$O$7)
A25: =$O$5 -> 184752 | B25: =IFERROR(_xlfn.XLOOKUP($O$5,DealsMaster[Deal No.],DealsMaster[Consignee]),"") -> Rubis Energy Zambia | D25: =IFERROR(_xlfn.XLOOKUP($O$5,DealsMaster[Deal No.],DealsMaster[Loading Port]),"") -> Beira | I25: =IFERROR(_xlfn.XLOOKUP($O$5,DealsMaster[Deal No.],DealsMaster[Destination]),"") -> Lusaka | J25: =IFERROR(_xlfn.XLOOKUP($O$5,DealsMaster[Deal No.],DealsMaster[Product]),"") -> PMS | M25: =IF(OR(K25="",L25=""),"",L25-K25) | N25: =$O$6 -> 2 | O25: =IF(AND(C25<>"",K25<>"",K25<C25),"⚠ Arrival < Loaded",IF(AND(K25<>"",L25<>"",L25<K25),"⚠ Offloaded < Arrival",IF(M25="","",IF(M25>N25,"DEMURRAGE","OK")))) | P25: =IF(M25="","",MAX(0,M25-N25)*$O$7)
A26: =$O$5 -> 184752 | B26: =IFERROR(_xlfn.XLOOKUP($O$5,DealsMaster[Deal No.],DealsMaster[Consignee]),"") -> Rubis Energy Zambia | D26: =IFERROR(_xlfn.XLOOKUP($O$5,DealsMaster[Deal No.],DealsMaster[Loading Port]),"") -> Beira | I26: =IFERROR(_xlfn.XLOOKUP($O$5,DealsMaster[Deal No.],DealsMaster[Destination]),"") -> Lusaka | J26: =IFERROR(_xlfn.XLOOKUP($O$5,DealsMaster[Deal No.],DealsMaster[Product]),"") -> PMS | M26: =IF(OR(K26="",L26=""),"",L26-K26) | N26: =$O$6 -> 2 | O26: =IF(AND(C26<>"",K26<>"",K26<C26),"⚠ Arrival < Loaded",IF(AND(K26<>"",L26<>"",L26<K26),"⚠ Offloaded < Arrival",IF(M26="","",IF(M26>N26,"DEMURRAGE","OK")))) | P26: =IF(M26="","",MAX(0,M26-N26)*$O$7)
A27: =$O$5 -> 184752 | B27: =IFERROR(_xlfn.XLOOKUP($O$5,DealsMaster[Deal No.],DealsMaster[Consignee]),"") -> Rubis Energy Zambia | D27: =IFERROR(_xlfn.XLOOKUP($O$5,DealsMaster[Deal No.],DealsMaster[Loading Port]),"") -> Beira | I27: =IFERROR(_xlfn.XLOOKUP($O$5,DealsMaster[Deal No.],DealsMaster[Destination]),"") -> Lusaka | J27: =IFERROR(_xlfn.XLOOKUP($O$5,DealsMaster[Deal No.],DealsMaster[Product]),"") -> PMS | M27: =IF(OR(K27="",L27=""),"",L27-K27) | N27: =$O$6 -> 2 | O27: =IF(AND(C27<>"",K27<>"",K27<C27),"⚠ Arrival < Loaded",IF(AND(K27<>"",L27<>"",L27<K27),"⚠ Offloaded < Arrival",IF(M27="","",IF(M27>N27,"DEMURRAGE","OK")))) | P27: =IF(M27="","",MAX(0,M27-N27)*$O$7)
A28: =$O$5 -> 184752 | B28: =IFERROR(_xlfn.XLOOKUP($O$5,DealsMaster[Deal No.],DealsMaster[Consignee]),"") -> Rubis Energy Zambia | D28: =IFERROR(_xlfn.XLOOKUP($O$5,DealsMaster[Deal No.],DealsMaster[Loading Port]),"") -> Beira | I28: =IFERROR(_xlfn.XLOOKUP($O$5,DealsMaster[Deal No.],DealsMaster[Destination]),"") -> Lusaka | J28: =IFERROR(_xlfn.XLOOKUP($O$5,DealsMaster[Deal No.],DealsMaster[Product]),"") -> PMS | M28: =IF(OR(K28="",L28=""),"",L28-K28) | N28: =$O$6 -> 2 | O28: =IF(AND(C28<>"",K28<>"",K28<C28),"⚠ Arrival < Loaded",IF(AND(K28<>"",L28<>"",L28<K28),"⚠ Offloaded < Arrival",IF(M28="","",IF(M28>N28,"DEMURRAGE","OK")))) | P28: =IF(M28="","",MAX(0,M28-N28)*$O$7)
A29: =$O$5 -> 184752 | B29: =IFERROR(_xlfn.XLOOKUP($O$5,DealsMaster[Deal No.],DealsMaster[Consignee]),"") -> Rubis Energy Zambia | D29: =IFERROR(_xlfn.XLOOKUP($O$5,DealsMaster[Deal No.],DealsMaster[Loading Port]),"") -> Beira | I29: =IFERROR(_xlfn.XLOOKUP($O$5,DealsMaster[Deal No.],DealsMaster[Destination]),"") -> Lusaka | J29: =IFERROR(_xlfn.XLOOKUP($O$5,DealsMaster[Deal No.],DealsMaster[Product]),"") -> PMS | M29: =IF(OR(K29="",L29=""),"",L29-K29) | N29: =$O$6 -> 2 | O29: =IF(AND(C29<>"",K29<>"",K29<C29),"⚠ Arrival < Loaded",IF(AND(K29<>"",L29<>"",L29<K29),"⚠ Offloaded < Arrival",IF(M29="","",IF(M29>N29,"DEMURRAGE","OK")))) | P29: =IF(M29="","",MAX(0,M29-N29)*$O$7)
A30: =$O$5 -> 184752 | B30: =IFERROR(_xlfn.XLOOKUP($O$5,DealsMaster[Deal No.],DealsMaster[Consignee]),"") -> Rubis Energy Zambia | D30: =IFERROR(_xlfn.XLOOKUP($O$5,DealsMaster[Deal No.],DealsMaster[Loading Port]),"") -> Beira | I30: =IFERROR(_xlfn.XLOOKUP($O$5,DealsMaster[Deal No.],DealsMaster[Destination]),"") -> Lusaka | J30: =IFERROR(_xlfn.XLOOKUP($O$5,DealsMaster[Deal No.],DealsMaster[Product]),"") -> PMS | M30: =IF(OR(K30="",L30=""),"",L30-K30) | N30: =$O$6 -> 2 | O30: =IF(AND(C30<>"",K30<>"",K30<C30),"⚠ Arrival < Loaded",IF(AND(K30<>"",L30<>"",L30<K30),"⚠ Offloaded < Arrival",IF(M30="","",IF(M30>N30,"DEMURRAGE","OK")))) | P30: =IF(M30="","",MAX(0,M30-N30)*$O$7)
A31: =$O$5 -> 184752 | B31: =IFERROR(_xlfn.XLOOKUP($O$5,DealsMaster[Deal No.],DealsMaster[Consignee]),"") -> Rubis Energy Zambia | D31: =IFERROR(_xlfn.XLOOKUP($O$5,DealsMaster[Deal No.],DealsMaster[Loading Port]),"") -> Beira | I31: =IFERROR(_xlfn.XLOOKUP($O$5,DealsMaster[Deal No.],DealsMaster[Destination]),"") -> Lusaka | J31: =IFERROR(_xlfn.XLOOKUP($O$5,DealsMaster[Deal No.],DealsMaster[Product]),"") -> PMS | M31: =IF(OR(K31="",L31=""),"",L31-K31) | N31: =$O$6 -> 2 | O31: =IF(AND(C31<>"",K31<>"",K31<C31),"⚠ Arrival < Loaded",IF(AND(K31<>"",L31<>"",L31<K31),"⚠ Offloaded < Arrival",IF(M31="","",IF(M31>N31,"DEMURRAGE","OK")))) | P31: =IF(M31="","",MAX(0,M31-N31)*$O$7)
A32: TOTAL | P32: =SUBTOTAL(109,P10:P31) -> 5500

Sheet 184834 - RELIANCE - BEIRA-LSK
C1: =IF(O5=0,"DEMURRAGE CALCULATION — [ENTER DEAL NO. ABOVE]","DEMURRAGE CALCULATION — "&TEXT(O5,"0")&" - "&UPPER(IFERROR(_xlfn.XLOOKUP(O5,DealsMaster[Deal No.],DealsMaster[Consignee]),""))&" - "&UPPER(IFERROR(_xlfn.XLOOKUP(O5,DealsMaster[Deal No.],DealsMaster[Route]),""))) -> DEMURRAGE CALCULATION — 184834 - RELIANCE ENERGY ZAMBIA - BEIRA → LUSAKA
C3: KEY METRICS
C4: TOTAL OWED | F4: # IN DEMURRAGE | N4: DEAL DEFAULTS
C5: =SUM('184834 - RELIANCE - BEIRA-LSK'!$P$10:$P$31) -> 0 | F5: =COUNTIF('184834 - RELIANCE - BEIRA-LSK'!$O$10:$O$31,"DEMURRAGE")&" / "&COUNTA('184834 - RELIANCE - BEIRA-LSK'!$A$10:$A$31) -> 0 / 22 | N5: Deal No. | O5: 184834
N6: Laytime (days) | O6: =IFERROR(_xlfn.XLOOKUP($O$5,DealsMaster[Deal No.],DealsMaster[Laytime Allowance (days)]),0) -> 2
N7: Rate (USD/day) | O7: =IFERROR(_xlfn.XLOOKUP($O$5,DealsMaster[Deal No.],DealsMaster[Demurrage Rate (USD/day)]),0) -> 250
A8: HOW TO USE: | B8: 1️⃣ Enter Deal No. in the gold box above → 2️⃣ Fill in truck details (columns C–L) row by row → 3️⃣ Demurrage calculates automatically → 4️⃣ Rename the sheet tab when done
A9: MOCOH Deal No. | B9: Consignee | C9: Date Loaded | D9: Loading Port | E9: Truck No. | F9: Trailer Reg. | G9: Transporter | H9: Driver Name | I9: Destination | J9: Product | K9: Arrival Date at Offloading | L9: Offloaded Date | M9: Total Waiting Days | N9: Laytime Used (days) | O9: Sanity Check | P9: Total Demurrage to Invoice (USD)
A10: =$O$5 -> 184834 | B10: =IFERROR(_xlfn.XLOOKUP($O$5,DealsMaster[Deal No.],DealsMaster[Consignee]),"") -> Reliance Energy Zambia | C10: 46011 | D10: =IFERROR(_xlfn.XLOOKUP($O$5,DealsMaster[Deal No.],DealsMaster[Loading Port]),"") -> Beira | E10: AKO080MC | F10: AH456MC | G10: PETRODA | H10: FERNANDO ULISSONE FERNANDO MATANDIRE | I10: =IFERROR(_xlfn.XLOOKUP($O$5,DealsMaster[Deal No.],DealsMaster[Destination]),"") -> Lusaka | J10: =IFERROR(_xlfn.XLOOKUP($O$5,DealsMaster[Deal No.],DealsMaster[Product]),"") -> PMS | K10: 46016 | L10: 46017 | M10: =IF(OR(K10="",L10=""),"",L10-K10) -> 1 | N10: =$O$6 -> 2 | O10: =IF(AND(C10<>"",K10<>"",K10<C10),"⚠ Arrival < Loaded",IF(AND(K10<>"",L10<>"",L10<K10),"⚠ Offloaded < Arrival",IF(M10="","",IF(M10>N10,"DEMURRAGE","OK")))) -> OK | P10: =IF(M10="","",MAX(0,M10-N10)*$O$7) -> 0
A11: =$O$5 -> 184834 | B11: =IFERROR(_xlfn.XLOOKUP($O$5,DealsMaster[Deal No.],DealsMaster[Consignee]),"") -> Reliance Energy Zambia | C11: 46011 | D11: =IFERROR(_xlfn.XLOOKUP($O$5,DealsMaster[Deal No.],DealsMaster[Loading Port]),"") -> Beira | E11: AKN021MC | F11: AH430MC | G11: PETRODA | H11: CHICONDI RAIMUNDO TEMBO | I11: =IFERROR(_xlfn.XLOOKUP($O$5,DealsMaster[Deal No.],DealsMaster[Destination]),"") -> Lusaka | J11: =IFERROR(_xlfn.XLOOKUP($O$5,DealsMaster[Deal No.],DealsMaster[Product]),"") -> PMS | K11: 46016 | L11: 46017 | M11: =IF(OR(K11="",L11=""),"",L11-K11) -> 1 | N11: =$O$6 -> 2 | O11: =IF(AND(C11<>"",K11<>"",K11<C11),"⚠ Arrival < Loaded",IF(AND(K11<>"",L11<>"",L11<K11),"⚠ Offloaded < Arrival",IF(M11="","",IF(M11>N11,"DEMURRAGE","OK")))) -> OK | P11: =IF(M11="","",MAX(0,M11-N11)*$O$7) -> 0
A12: =$O$5 -> 184834 | B12: =IFERROR(_xlfn.XLOOKUP($O$5,DealsMaster[Deal No.],DealsMaster[Consignee]),"") -> Reliance Energy Zambia | C12: 46011 | D12: =IFERROR(_xlfn.XLOOKUP($O$5,DealsMaster[Deal No.],DealsMaster[Loading Port]),"") -> Beira | E12: AK0101MC | F12: AH451MC | G12: PETRODA | H12: PEREIRA FERNANDO ARGOLA | I12: =IFERROR(_xlfn.XLOOKUP($O$5,DealsMaster[Deal No.],DealsMaster[Destination]),"") -> Lusaka | J12: =IFERROR(_xlfn.XLOOKUP($O$5,DealsMaster[Deal No.],DealsMaster[Product]),"") -> PMS | K12: 46015 | L12: 46015 | M12: =IF(OR(K12="",L12=""),"",L12-K12) -> 0 | N12: =$O$6 -> 2 | O12: =IF(AND(C12<>"",K12<>"",K12<C12),"⚠ Arrival < Loaded",IF(AND(K12<>"",L12<>"",L12<K12),"⚠ Offloaded < Arrival",IF(M12="","",IF(M12>N12,"DEMURRAGE","OK")))) -> OK | P12: =IF(M12="","",MAX(0,M12-N12)*$O$7) -> 0
A13: =$O$5 -> 184834 | B13: =IFERROR(_xlfn.XLOOKUP($O$5,DealsMaster[Deal No.],DealsMaster[Consignee]),"") -> Reliance Energy Zambia | C13: 46011 | D13: =IFERROR(_xlfn.XLOOKUP($O$5,DealsMaster[Deal No.],DealsMaster[Loading Port]),"") -> Beira | E13: AKN812MC | F13: AH439MC | G13: PETRODA | H13: MOISES BACALEUANE ARROZ | I13: =IFERROR(_xlfn.XLOOKUP($O$5,DealsMaster[Deal No.],DealsMaster[Destination]),"") -> Lusaka | J13: =IFERROR(_xlfn.XLOOKUP($O$5,DealsMaster[Deal No.],DealsMaster[Product]),"") -> PMS | K13: 46015 | L13: 46015 | M13: =IF(OR(K13="",L13=""),"",L13-K13) -> 0 | N13: =$O$6 -> 2 | O13: =IF(AND(C13<>"",K13<>"",K13<C13),"⚠ Arrival < Loaded",IF(AND(K13<>"",L13<>"",L13<K13),"⚠ Offloaded < Arrival",IF(M13="","",IF(M13>N13,"DEMURRAGE","OK")))) -> OK | P13: =IF(M13="","",MAX(0,M13-N13)*$O$7) -> 0
A14: =$O$5 -> 184834 | B14: =IFERROR(_xlfn.XLOOKUP($O$5,DealsMaster[Deal No.],DealsMaster[Consignee]),"") -> Reliance Energy Zambia | D14: =IFERROR(_xlfn.XLOOKUP($O$5,DealsMaster[Deal No.],DealsMaster[Loading Port]),"") -> Beira | I14: =IFERROR(_xlfn.XLOOKUP($O$5,DealsMaster[Deal No.],DealsMaster[Destination]),"") -> Lusaka | J14: =IFERROR(_xlfn.XLOOKUP($O$5,DealsMaster[Deal No.],DealsMaster[Product]),"") -> PMS | M14: =IF(OR(K14="",L14=""),"",L14-K14) | N14: =$O$6 -> 2 | O14: =IF(AND(C14<>"",K14<>"",K14<C14),"⚠ Arrival < Loaded",IF(AND(K14<>"",L14<>"",L14<K14),"⚠ Offloaded < Arrival",IF(M14="","",IF(M14>N14,"DEMURRAGE","OK")))) | P14: =IF(M14="","",MAX(0,M14-N14)*$O$7)
A15: =$O$5 -> 184834 | B15: =IFERROR(_xlfn.XLOOKUP($O$5,DealsMaster[Deal No.],DealsMaster[Consignee]),"") -> Reliance Energy Zambia | D15: =IFERROR(_xlfn.XLOOKUP($O$5,DealsMaster[Deal No.],DealsMaster[Loading Port]),"") -> Beira | I15: =IFERROR(_xlfn.XLOOKUP($O$5,DealsMaster[Deal No.],DealsMaster[Destination]),"") -> Lusaka | J15: =IFERROR(_xlfn.XLOOKUP($O$5,DealsMaster[Deal No.],DealsMaster[Product]),"") -> PMS | M15: =IF(OR(K15="",L15=""),"",L15-K15) | N15: =$O$6 -> 2 | O15: =IF(AND(C15<>"",K15<>"",K15<C15),"⚠ Arrival < Loaded",IF(AND(K15<>"",L15<>"",L15<K15),"⚠ Offloaded < Arrival",IF(M15="","",IF(M15>N15,"DEMURRAGE","OK")))) | P15: =IF(M15="","",MAX(0,M15-N15)*$O$7)
A16: =$O$5 -> 184834 | B16: =IFERROR(_xlfn.XLOOKUP($O$5,DealsMaster[Deal No.],DealsMaster[Consignee]),"") -> Reliance Energy Zambia | D16: =IFERROR(_xlfn.XLOOKUP($O$5,DealsMaster[Deal No.],DealsMaster[Loading Port]),"") -> Beira | I16: =IFERROR(_xlfn.XLOOKUP($O$5,DealsMaster[Deal No.],DealsMaster[Destination]),"") -> Lusaka | J16: =IFERROR(_xlfn.XLOOKUP($O$5,DealsMaster[Deal No.],DealsMaster[Product]),"") -> PMS | M16: =IF(OR(K16="",L16=""),"",L16-K16) | N16: =$O$6 -> 2 | O16: =IF(AND(C16<>"",K16<>"",K16<C16),"⚠ Arrival < Loaded",IF(AND(K16<>"",L16<>"",L16<K16),"⚠ Offloaded < Arrival",IF(M16="","",IF(M16>N16,"DEMURRAGE","OK")))) | P16: =IF(M16="","",MAX(0,M16-N16)*$O$7)
A17: =$O$5 -> 184834 | B17: =IFERROR(_xlfn.XLOOKUP($O$5,DealsMaster[Deal No.],DealsMaster[Consignee]),"") -> Reliance Energy Zambia | D17: =IFERROR(_xlfn.XLOOKUP($O$5,DealsMaster[Deal No.],DealsMaster[Loading Port]),"") -> Beira | I17: =IFERROR(_xlfn.XLOOKUP($O$5,DealsMaster[Deal No.],DealsMaster[Destination]),"") -> Lusaka | J17: =IFERROR(_xlfn.XLOOKUP($O$5,DealsMaster[Deal No.],DealsMaster[Product]),"") -> PMS | M17: =IF(OR(K17="",L17=""),"",L17-K17) | N17: =$O$6 -> 2 | O17: =IF(AND(C17<>"",K17<>"",K17<C17),"⚠ Arrival < Loaded",IF(AND(K17<>"",L17<>"",L17<K17),"⚠ Offloaded < Arrival",IF(M17="","",IF(M17>N17,"DEMURRAGE","OK")))) | P17: =IF(M17="","",MAX(0,M17-N17)*$O$7)
A18: =$O$5 -> 184834 | B18: =IFERROR(_xlfn.XLOOKUP($O$5,DealsMaster[Deal No.],DealsMaster[Consignee]),"") -> Reliance Energy Zambia | D18: =IFERROR(_xlfn.XLOOKUP($O$5,DealsMaster[Deal No.],DealsMaster[Loading Port]),"") -> Beira | I18: =IFERROR(_xlfn.XLOOKUP($O$5,DealsMaster[Deal No.],DealsMaster[Destination]),"") -> Lusaka | J18: =IFERROR(_xlfn.XLOOKUP($O$5,DealsMaster[Deal No.],DealsMaster[Product]),"") -> PMS | M18: =IF(OR(K18="",L18=""),"",L18-K18) | N18: =$O$6 -> 2 | O18: =IF(AND(C18<>"",K18<>"",K18<C18),"⚠ Arrival < Loaded",IF(AND(K18<>"",L18<>"",L18<K18),"⚠ Offloaded < Arrival",IF(M18="","",IF(M18>N18,"DEMURRAGE","OK")))) | P18: =IF(M18="","",MAX(0,M18-N18)*$O$7)
A19: =$O$5 -> 184834 | B19: =IFERROR(_xlfn.XLOOKUP($O$5,DealsMaster[Deal No.],DealsMaster[Consignee]),"") -> Reliance Energy Zambia | D19: =IFERROR(_xlfn.XLOOKUP($O$5,DealsMaster[Deal No.],DealsMaster[Loading Port]),"") -> Beira | I19: =IFERROR(_xlfn.XLOOKUP($O$5,DealsMaster[Deal No.],DealsMaster[Destination]),"") -> Lusaka | J19: =IFERROR(_xlfn.XLOOKUP($O$5,DealsMaster[Deal No.],DealsMaster[Product]),"") -> PMS | M19: =IF(OR(K19="",L19=""),"",L19-K19) | N19: =$O$6 -> 2 | O19: =IF(AND(C19<>"",K19<>"",K19<C19),"⚠ Arrival < Loaded",IF(AND(K19<>"",L19<>"",L19<K19),"⚠ Offloaded < Arrival",IF(M19="","",IF(M19>N19,"DEMURRAGE","OK")))) | P19: =IF(M19="","",MAX(0,M19-N19)*$O$7)
A20: =$O$5 -> 184834 | B20: =IFERROR(_xlfn.XLOOKUP($O$5,DealsMaster[Deal No.],DealsMaster[Consignee]),"") -> Reliance Energy Zambia | D20: =IFERROR(_xlfn.XLOOKUP($O$5,DealsMaster[Deal No.],DealsMaster[Loading Port]),"") -> Beira | I20: =IFERROR(_xlfn.XLOOKUP($O$5,DealsMaster[Deal No.],DealsMaster[Destination]),"") -> Lusaka | J20: =IFERROR(_xlfn.XLOOKUP($O$5,DealsMaster[Deal No.],DealsMaster[Product]),"") -> PMS | M20: =IF(OR(K20="",L20=""),"",L20-K20) | N20: =$O$6 -> 2 | O20: =IF(AND(C20<>"",K20<>"",K20<C20),"⚠ Arrival < Loaded",IF(AND(K20<>"",L20<>"",L20<K20),"⚠ Offloaded < Arrival",IF(M20="","",IF(M20>N20,"DEMURRAGE","OK")))) | P20: =IF(M20="","",MAX(0,M20-N20)*$O$7)
A21: =$O$5 -> 184834 | B21: =IFERROR(_xlfn.XLOOKUP($O$5,DealsMaster[Deal No.],DealsMaster[Consignee]),"") -> Reliance Energy Zambia | D21: =IFERROR(_xlfn.XLOOKUP($O$5,DealsMaster[Deal No.],DealsMaster[Loading Port]),"") -> Beira | I21: =IFERROR(_xlfn.XLOOKUP($O$5,DealsMaster[Deal No.],DealsMaster[Destination]),"") -> Lusaka | J21: =IFERROR(_xlfn.XLOOKUP($O$5,DealsMaster[Deal No.],DealsMaster[Product]),"") -> PMS | M21: =IF(OR(K21="",L21=""),"",L21-K21) | N21: =$O$6 -> 2 | O21: =IF(AND(C21<>"",K21<>"",K21<C21),"⚠ Arrival < Loaded",IF(AND(K21<>"",L21<>"",L21<K21),"⚠ Offloaded < Arrival",IF(M21="","",IF(M21>N21,"DEMURRAGE","OK")))) | P21: =IF(M21="","",MAX(0,M21-N21)*$O$7)
A22: =$O$5 -> 184834 | B22: =IFERROR(_xlfn.XLOOKUP($O$5,DealsMaster[Deal No.],DealsMaster[Consignee]),"") -> Reliance Energy Zambia | D22: =IFERROR(_xlfn.XLOOKUP($O$5,DealsMaster[Deal No.],DealsMaster[Loading Port]),"") -> Beira | I22: =IFERROR(_xlfn.XLOOKUP($O$5,DealsMaster[Deal No.],DealsMaster[Destination]),"") -> Lusaka | J22: =IFERROR(_xlfn.XLOOKUP($O$5,DealsMaster[Deal No.],DealsMaster[Product]),"") -> PMS | M22: =IF(OR(K22="",L22=""),"",L22-K22) | N22: =$O$6 -> 2 | O22: =IF(AND(C22<>"",K22<>"",K22<C22),"⚠ Arrival < Loaded",IF(AND(K22<>"",L22<>"",L22<K22),"⚠ Offloaded < Arrival",IF(M22="","",IF(M22>N22,"DEMURRAGE","OK")))) | P22: =IF(M22="","",MAX(0,M22-N22)*$O$7)
A23: =$O$5 -> 184834 | B23: =IFERROR(_xlfn.XLOOKUP($O$5,DealsMaster[Deal No.],DealsMaster[Consignee]),"") -> Reliance Energy Zambia | D23: =IFERROR(_xlfn.XLOOKUP($O$5,DealsMaster[Deal No.],DealsMaster[Loading Port]),"") -> Beira | I23: =IFERROR(_xlfn.XLOOKUP($O$5,DealsMaster[Deal No.],DealsMaster[Destination]),"") -> Lusaka | J23: =IFERROR(_xlfn.XLOOKUP($O$5,DealsMaster[Deal No.],DealsMaster[Product]),"") -> PMS | M23: =IF(OR(K23="",L23=""),"",L23-K23) | N23: =$O$6 -> 2 | O23: =IF(AND(C23<>"",K23<>"",K23<C23),"⚠ Arrival < Loaded",IF(AND(K23<>"",L23<>"",L23<K23),"⚠ Offloaded < Arrival",IF(M23="","",IF(M23>N23,"DEMURRAGE","OK")))) | P23: =IF(M23="","",MAX(0,M23-N23)*$O$7)
A24: =$O$5 -> 184834 | B24: =IFERROR(_xlfn.XLOOKUP($O$5,DealsMaster[Deal No.],DealsMaster[Consignee]),"") -> Reliance Energy Zambia | D24: =IFERROR(_xlfn.XLOOKUP($O$5,DealsMaster[Deal No.],DealsMaster[Loading Port]),"") -> Beira | I24: =IFERROR(_xlfn.XLOOKUP($O$5,DealsMaster[Deal No.],DealsMaster[Destination]),"") -> Lusaka | J24: =IFERROR(_xlfn.XLOOKUP($O$5,DealsMaster[Deal No.],DealsMaster[Product]),"") -> PMS | M24: =IF(OR(K24="",L24=""),"",L24-K24) | N24: =$O$6 -> 2 | O24: =IF(AND(C24<>"",K24<>"",K24<C24),"⚠ Arrival < Loaded",IF(AND(K24<>"",L24<>"",L24<K24),"⚠ Offloaded < Arrival",IF(M24="","",IF(M24>N24,"DEMURRAGE","OK")))) | P24: =IF(M24="","",MAX(0,M24-N24)*$O$7)
A25: =$O$5 -> 184834 | B25: =IFERROR(_xlfn.XLOOKUP($O$5,DealsMaster[Deal No.],DealsMaster[Consignee]),"") -> Reliance Energy Zambia | D25: =IFERROR(_xlfn.XLOOKUP($O$5,DealsMaster[Deal No.],DealsMaster[Loading Port]),"") -> Beira | I25: =IFERROR(_xlfn.XLOOKUP($O$5,DealsMaster[Deal No.],DealsMaster[Destination]),"") -> Lusaka | J25: =IFERROR(_xlfn.XLOOKUP($O$5,DealsMaster[Deal No.],DealsMaster[Product]),"") -> PMS | M25: =IF(OR(K25="",L25=""),"",L25-K25) | N25: =$O$6 -> 2 | O25: =IF(AND(C25<>"",K25<>"",K25<C25),"⚠ Arrival < Loaded",IF(AND(K25<>"",L25<>"",L25<K25),"⚠ Offloaded < Arrival",IF(M25="","",IF(M25>N25,"DEMURRAGE","OK")))) | P25: =IF(M25="","",MAX(0,M25-N25)*$O$7)
... A31: =$O$5 -> 184834 | B31: =IFERROR(_xlfn.XLOOKUP($O$5,DealsMaster[Deal No.],DealsMaster[Consignee]),"") -> Reliance Energy Zambia | D31: =IFERROR(_xlfn.XLOOKUP($O$5,DealsMaster[Deal No.],DealsMaster[Loading Port]),"") -> Beira | I31: =IFERROR(_xlfn.XLOOKUP($O$5,DealsMaster[Deal No.],DealsMaster[Destination]),"") -> Lusaka | J31: =IFERROR(_xlfn.XLOOKUP($O$5,DealsMaster[Deal No.],DealsMaster[Product]),"") -> PMS | M31: =IF(OR(K31="",L31=""),"",L31-K31) | N31: =$O$6 -> 2 | O31: =IF(AND(C31<>"",K31<>"",K31<C31),"⚠ Arrival < Loaded",IF(AND(K31<>"",L31<>"",L31<K31),"⚠ Offloaded < Arrival",IF(M31="","",IF(M31>N31,"DEMURRAGE","OK")))) | P31: =IF(M31="","",MAX(0,M31-N31)*$O$7)
A32: TOTAL | P32: =SUBTOTAL(109,P10:P31) -> 0

Sheet 186216-RUBIS-BEIRA-LSK
C1: =IF(O5=0,"DEMURRAGE CALCULATION — [ENTER DEAL NO. ABOVE]","DEMURRAGE CALCULATION — "&TEXT(O5,"0")&" - "&UPPER(IFERROR(_xlfn.XLOOKUP(O5,DealsMaster[Deal No.],DealsMaster[Consignee]),""))&" - "&UPPER(IFERROR(_xlfn.XLOOKUP(O5,DealsMaster[Deal No.],DealsMaster[Route]),""))) -> DEMURRAGE CALCULATION — 186216 - RUBIS ENERGY ZAMBIA - BEIRA → LUSAKA
C3: KEY METRICS
C4: TOTAL OWED | F4: # IN DEMURRAGE | N4: DEAL DEFAULTS
C5: =SUM('186216-RUBIS-BEIRA-LSK'!$P$10:$P$31) -> 1500 | F5: =COUNTIF('186216-RUBIS-BEIRA-LSK'!$O$10:$O$31,"DEMURRAGE")&" / "&COUNTA('186216-RUBIS-BEIRA-LSK'!$A$10:$A$31) -> 1 / 22 | N5: Deal No. | O5: 186216
N6: Laytime (days) | O6: =IFERROR(_xlfn.XLOOKUP($O$5,DealsMaster[Deal No.],DealsMaster[Laytime Allowance (days)]),0) -> 2
N7: Rate (USD/day) | O7: =IFERROR(_xlfn.XLOOKUP($O$5,DealsMaster[Deal No.],DealsMaster[Demurrage Rate (USD/day)]),0) -> 250
A8: HOW TO USE: | B8: 1️⃣ Enter Deal No. in the gold box above → 2️⃣ Fill in truck details (columns C–L) row by row → 3️⃣ Demurrage calculates automatically → 4️⃣ Rename the sheet tab when done
A9: MOCOH Deal No. | B9: Consignee | C9: Date Loaded | D9: Loading Port | E9: Truck No. | F9: Trailer Reg. | G9: Transporter | H9: Driver Name | I9: Destination | J9: Product | K9: Arrival Date at Offloading | L9: Offloaded Date | M9: Total Waiting Days | N9: Laytime Used (days) | O9: Sanity Check | P9: Total Demurrage to Invoice (USD)
A10: =$O$5 -> 186216 | B10: =IFERROR(_xlfn.XLOOKUP($O$5,DealsMaster[Deal No.],DealsMaster[Consignee]),"") -> Rubis Energy Zambia | D10: =IFERROR(_xlfn.XLOOKUP($O$5,DealsMaster[Deal No.],DealsMaster[Loading Port]),"") -> Beira | E10: AGU 496 MP | F10: AF 738 MC | G10: TRANSIR | H10: Nhamo Mukwekwerere | I10: =IFERROR(_xlfn.XLOOKUP($O$5,DealsMaster[Deal No.],DealsMaster[Destination]),"") -> Lusaka | J10: =IFERROR(_xlfn.XLOOKUP($O$5,DealsMaster[Deal No.],DealsMaster[Product]),"") -> PMS | K10: 46071 | L10: 46073 | M10: =IF(OR(K10="",L10=""),"",L10-K10) -> 2 | N10: =$O$6 -> 2 | O10: =IF(AND(C10<>"",K10<>"",K10<C10),"⚠ Arrival < Loaded",IF(AND(K10<>"",L10<>"",L10<K10),"⚠ Offloaded < Arrival",IF(M10="","",IF(M10>N10,"DEMURRAGE","OK")))) -> OK | P10: =IF(M10="","",MAX(0,M10-N10)*$O$7) -> 0
A11: =$O$5 -> 186216 | B11: =IFERROR(_xlfn.XLOOKUP($O$5,DealsMaster[Deal No.],DealsMaster[Consignee]),"") -> Rubis Energy Zambia | D11: =IFERROR(_xlfn.XLOOKUP($O$5,DealsMaster[Deal No.],DealsMaster[Loading Port]),"") -> Beira | E11: AJJ 602 MP | F11: AF 699 MC | G11: TRANSIR | H11: Hestings Banda | I11: =IFERROR(_xlfn.XLOOKUP($O$5,DealsMaster[Deal No.],DealsMaster[Destination]),"") -> Lusaka | J11: =IFERROR(_xlfn.XLOOKUP($O$5,DealsMaster[Deal No.],DealsMaster[Product]),"") -> PMS | K11: 46074 | L11: 46076 | M11: =IF(OR(K11="",L11=""),"",L11-K11) -> 2 | N11: =$O$6 -> 2 | O11: =IF(AND(C11<>"",K11<>"",K11<C11),"⚠ Arrival < Loaded",IF(AND(K11<>"",L11<>"",L11<K11),"⚠ Offloaded < Arrival",IF(M11="","",IF(M11>N11,"DEMURRAGE","OK")))) -> OK | P11: =IF(M11="","",MAX(0,M11-N11)*$O$7) -> 0
A12: =$O$5 -> 186216 | B12: =IFERROR(_xlfn.XLOOKUP($O$5,DealsMaster[Deal No.],DealsMaster[Consignee]),"") -> Rubis Energy Zambia | D12: =IFERROR(_xlfn.XLOOKUP($O$5,DealsMaster[Deal No.],DealsMaster[Loading Port]),"") -> Beira | E12: AFW 378 MP | F12: AE 731 MC | G12: TRANSIR | H12: Kangai Tafirenyika | I12: =IFERROR(_xlfn.XLOOKUP($O$5,DealsMaster[Deal No.],DealsMaster[Destination]),"") -> Lusaka | J12: =IFERROR(_xlfn.XLOOKUP($O$5,DealsMaster[Deal No.],DealsMaster[Product]),"") -> PMS | K12: 46074 | L12: 46076 | M12: =IF(OR(K12="",L12=""),"",L12-K12) -> 2 | N12: =$O$6 -> 2 | O12: =IF(AND(C12<>"",K12<>"",K12<C12),"⚠ Arrival < Loaded",IF(AND(K12<>"",L12<>"",L12<K12),"⚠ Offloaded < Arrival",IF(M12="","",IF(M12>N12,"DEMURRAGE","OK")))) -> OK | P12: =IF(M12="","",MAX(0,M12-N12)*$O$7) -> 0
A13: =$O$5 -> 186216 | B13: =IFERROR(_xlfn.XLOOKUP($O$5,DealsMaster[Deal No.],DealsMaster[Consignee]),"") -> Rubis Energy Zambia | D13: =IFERROR(_xlfn.XLOOKUP($O$5,DealsMaster[Deal No.],DealsMaster[Loading Port]),"") -> Beira | E13: AIB 049 MC | F13: AF 715 MC | G13: TRANSIR | H13: Kumirai Krispen | I13: =IFERROR(_xlfn.XLOOKUP($O$5,DealsMaster[Deal No.],DealsMaster[Destination]),"") -> Lusaka | J13: =IFERROR(_xlfn.XLOOKUP($O$5,DealsMaster[Deal No.],DealsMaster[Product]),"") -> PMS | K13: 46080 | L13: 46088 | M13: =IF(OR(K13="",L13=""),"",L13-K13) -> 8 | N13: =$O$6 -> 2 | O13: =IF(AND(C13<>"",K13<>"",K13<C13),"⚠ Arrival < Loaded",IF(AND(K13<>"",L13<>"",L13<K13),"⚠ Offloaded < Arrival",IF(M13="","",IF(M13>N13,"DEMURRAGE","OK")))) -> DEMURRAGE | P13: =IF(M13="","",MAX(0,M13-N13)*$O$7) -> 1500
A14: =$O$5 -> 186216 | B14: =IFERROR(_xlfn.XLOOKUP($O$5,DealsMaster[Deal No.],DealsMaster[Consignee]),"") -> Rubis Energy Zambia | O14: =IF(AND(C14<>"",K14<>"",K14<C14),"⚠ Arrival < Loaded",IF(AND(K14<>"",L14<>"",L14<K14),"⚠ Offloaded < Arrival",IF(M14="","",IF(M14>N14,"DEMURRAGE","OK")))) | P14: =IF(M14="","",MAX(0,M14-N14)*$O$7)
A15: =$O$5 -> 186216 | B15: =IFERROR(_xlfn.XLOOKUP($O$5,DealsMaster[Deal No.],DealsMaster[Consignee]),"") -> Rubis Energy Zambia | O15: =IF(AND(C15<>"",K15<>"",K15<C15),"⚠ Arrival < Loaded",IF(AND(K15<>"",L15<>"",L15<K15),"⚠ Offloaded < Arrival",IF(M15="","",IF(M15>N15,"DEMURRAGE","OK")))) | P15: =IF(M15="","",MAX(0,M15-N15)*$O$7)
A16: =$O$5 -> 186216 | B16: =IFERROR(_xlfn.XLOOKUP($O$5,DealsMaster[Deal No.],DealsMaster[Consignee]),"") -> Rubis Energy Zambia | O16: =IF(AND(C16<>"",K16<>"",K16<C16),"⚠ Arrival < Loaded",IF(AND(K16<>"",L16<>"",L16<K16),"⚠ Offloaded < Arrival",IF(M16="","",IF(M16>N16,"DEMURRAGE","OK")))) | P16: =IF(M16="","",MAX(0,M16-N16)*$O$7)
A17: =$O$5 -> 186216 | B17: =IFERROR(_xlfn.XLOOKUP($O$5,DealsMaster[Deal No.],DealsMaster[Consignee]),"") -> Rubis Energy Zambia | O17: =IF(AND(C17<>"",K17<>"",K17<C17),"⚠ Arrival < Loaded",IF(AND(K17<>"",L17<>"",L17<K17),"⚠ Offloaded < Arrival",IF(M17="","",IF(M17>N17,"DEMURRAGE","OK")))) | P17: =IF(M17="","",MAX(0,M17-N17)*$O$7)
A18: =$O$5 -> 186216 | B18: =IFERROR(_xlfn.XLOOKUP($O$5,DealsMaster[Deal No.],DealsMaster[Consignee]),"") -> Rubis Energy Zambia | O18: =IF(AND(C18<>"",K18<>"",K18<C18),"⚠ Arrival < Loaded",IF(AND(K18<>"",L18<>"",L18<K18),"⚠ Offloaded < Arrival",IF(M18="","",IF(M18>N18,"DEMURRAGE","OK")))) | P18: =IF(M18="","",MAX(0,M18-N18)*$O$7)
A19: =$O$5 -> 186216 | B19: =IFERROR(_xlfn.XLOOKUP($O$5,DealsMaster[Deal No.],DealsMaster[Consignee]),"") -> Rubis Energy Zambia | O19: =IF(AND(C19<>"",K19<>"",K19<C19),"⚠ Arrival < Loaded",IF(AND(K19<>"",L19<>"",L19<K19),"⚠ Offloaded < Arrival",IF(M19="","",IF(M19>N19,"DEMURRAGE","OK")))) | P19: =IF(M19="","",MAX(0,M19-N19)*$O$7)
A20: =$O$5 -> 186216 | B20: =IFERROR(_xlfn.XLOOKUP($O$5,DealsMaster[Deal No.],DealsMaster[Consignee]),"") -> Rubis Energy Zambia | O20: =IF(AND(C20<>"",K20<>"",K20<C20),"⚠ Arrival < Loaded",IF(AND(K20<>"",L20<>"",L20<K20),"⚠ Offloaded < Arrival",IF(M20="","",IF(M20>N20,"DEMURRAGE","OK")))) | P20: =IF(M20="","",MAX(0,M20-N20)*$O$7)
A21: =$O$5 -> 186216 | B21: =IFERROR(_xlfn.XLOOKUP($O$5,DealsMaster[Deal No.],DealsMaster[Consignee]),"") -> Rubis Energy Zambia | O21: =IF(AND(C21<>"",K21<>"",K21<C21),"⚠ Arrival < Loaded",IF(AND(K21<>"",L21<>"",L21<K21),"⚠ Offloaded < Arrival",IF(M21="","",IF(M21>N21,"DEMURRAGE","OK")))) | P21: =IF(M21="","",MAX(0,M21-N21)*$O$7)
A22: =$O$5 -> 186216 | B22: =IFERROR(_xlfn.XLOOKUP($O$5,DealsMaster[Deal No.],DealsMaster[Consignee]),"") -> Rubis Energy Zambia | O22: =IF(AND(C22<>"",K22<>"",K22<C22),"⚠ Arrival < Loaded",IF(AND(K22<>"",L22<>"",L22<K22),"⚠ Offloaded < Arrival",IF(M22="","",IF(M22>N22,"DEMURRAGE","OK")))) | P22: =IF(M22="","",MAX(0,M22-N22)*$O$7)
A23: =$O$5 -> 186216 | B23: =IFERROR(_xlfn.XLOOKUP($O$5,DealsMaster[Deal No.],DealsMaster[Consignee]),"") -> Rubis Energy Zambia | O23: =IF(AND(C23<>"",K23<>"",K23<C23),"⚠ Arrival < Loaded",IF(AND(K23<>"",L23<>"",L23<K23),"⚠ Offloaded < Arrival",IF(M23="","",IF(M23>N23,"DEMURRAGE","OK")))) | P23: =IF(M23="","",MAX(0,M23-N23)*$O$7)
A24: =$O$5 -> 186216 | B24: =IFERROR(_xlfn.XLOOKUP($O$5,DealsMaster[Deal No.],DealsMaster[Consignee]),"") -> Rubis Energy Zambia | O24: =IF(AND(C24<>"",K24<>"",K24<C24),"⚠ Arrival < Loaded",IF(AND(K24<>"",L24<>"",L24<K24),"⚠ Offloaded < Arrival",IF(M24="","",IF(M24>N24,"DEMURRAGE","OK")))) | P24: =IF(M24="","",MAX(0,M24-N24)*$O$7)
A25: =$O$5 -> 186216 | B25: =IFERROR(_xlfn.XLOOKUP($O$5,DealsMaster[Deal No.],DealsMaster[Consignee]),"") -> Rubis Energy Zambia | O25: =IF(AND(C25<>"",K25<>"",K25<C25),"⚠ Arrival < Loaded",IF(AND(K25<>"",L25<>"",L25<K25),"⚠ Offloaded < Arrival",IF(M25="","",IF(M25>N25,"DEMURRAGE","OK")))) | P25: =IF(M25="","",MAX(0,M25-N25)*$O$7)
... A31: =$O$5 -> 186216 | B31: =IFERROR(_xlfn.XLOOKUP($O$5,DealsMaster[Deal No.],DealsMaster[Consignee]),"") -> Rubis Energy Zambia | O31: =IF(AND(C31<>"",K31<>"",K31<C31),"⚠ Arrival < Loaded",IF(AND(K31<>"",L31<>"",L31<K31),"⚠ Offloaded < Arrival",IF(M31="","",IF(M31>N31,"DEMURRAGE","OK")))) | P31: =IF(M31="","",MAX(0,M31-N31)*$O$7)
A32: TOTAL | P32: =SUBTOTAL(109,P10:P31) -> 1500

Sheet 187293-LAKE-BEIRA-LSK
C1: =IF(O5=0,"DEMURRAGE CALCULATION — [ENTER DEAL NO. ABOVE]","DEMURRAGE CALCULATION — "&TEXT(O5,"0")&" - "&UPPER(IFERROR(_xlfn.XLOOKUP(O5,DealsMaster[Deal No.],DealsMaster[Consignee]),""))&" - "&UPPER(IFERROR(_xlfn.XLOOKUP(O5,DealsMaster[Deal No.],DealsMaster[Route]),""))) -> DEMURRAGE CALCULATION — 187293 - LAKE PETROLEUM ZAMBIA - BEIRA → LUSAKA
C3: KEY METRICS
C4: TOTAL OWED | F4: # IN DEMURRAGE | N4: DEAL DEFAULTS
C5: =SUM('187293-LAKE-BEIRA-LSK'!$P$10:$P$38) -> 50750 | F5: =COUNTIF('187293-LAKE-BEIRA-LSK'!$O$10:$O$38,"DEMURRAGE")&" / "&COUNTA('187293-LAKE-BEIRA-LSK'!$A$10:$A$38) -> 29 / 29 | N5: Deal No. | O5: 187293
N6: Laytime (days) | O6: =IFERROR(_xlfn.XLOOKUP($O$5,DealsMaster[Deal No.],DealsMaster[Laytime Allowance (days)]),0) -> 2
N7: Rate (USD/day) | O7: =IFERROR(_xlfn.XLOOKUP($O$5,DealsMaster[Deal No.],DealsMaster[Demurrage Rate (USD/day)]),0) -> 250
A8: HOW TO USE: | B8: 1️⃣ Enter Deal No. in the gold box above → 2️⃣ Fill in truck details (columns C–L) row by row → 3️⃣ Demurrage calculates automatically → 4️⃣ Rename the sheet tab when done
A9: MOCOH Deal No. | B9: Consignee | C9: Date Loaded | D9: Loading Port | E9: Truck No. | F9: Trailer Reg. | G9: Transporter | H9: Driver Name | I9: Destination | J9: Product | K9: Arrival Date at Offloading | L9: Offloaded Date | M9: Total Waiting Days | N9: Laytime Allowed (days) | O9: Sanity Check | P9: Total Demurrage to Invoice (USD)
